Workbook

Sheet 1. Data Transaksi
A1: ID_Transaksi | B1: Tanggal | C1: ID_Pelanggan | D1: ID_Layanan | E1: Area | F1: KWh_Terpakai | G1: Status_Bayar
A2: TRX0001 | B2: 46255 | C2: PLN-4598 | D2: B1-450 | F2: 239 | G2: Lunas
A3: TRX0002 | B3: 46120 | C3: PLN-6313 | D3: B1-450 | E3: Jakarta | F3: 188 | G3: Lunas
A4: TRX0003 | B4: 46030 | C4: PLN-1916 | D4: R1-900 | E4: Tangerang | F4: 251 | G4: Lunas
A5: TRX0004 | B5: 46258 | C5: PLN-4752 | D5: R1-450 | E5: jkt | F5: 321 | G5: Lunas
A6: TRX0005 | B6: 46273 | C6: PLN-1525 | D6: R1-450 | E6: Bekasi | F6: 181 | G6: Lunas
A7: TRX0006 | B7: 46242 | C7: PLN-6168 | D7: B1-1300 | E7: Jakarta | F7: 181 | G7: Lunas
A8: TRX0007 | B8: 46242 | C8: PLN-7572 | D8: B1-450 | E8: Jakarta | F8: 326 | G8: Lunas
A9: TRX0008 | B9: 46150 | C9: PLN-5386 | D9: R1-1300 | E9: Bekasi | F9: 261 | G9: Lunas
A10: TRX0009 | B10: 46303 | D10: B1-450 | E10: Tangerang | F10: 162 | G10: Lunas
A11: TRX0010 | B11: 46257 | C11: PLN-9494 | D11: R1-1300 | E11: Tangerang | F11: 243 | G11: Tunggakan
A12: TRX0011 | B12: 46089 | C12: PLN-1132 | D12: B1-450 | E12: Bogor | F12: 162 | G12: Lunas
A13: TRX0012 | B13: 46256 | C13: PLN-2321 | D13: R1-450 | E13: Depok | F13: 162 | G13: Lunas
A14: TRX0013 | B14: 46334 | C14: PLN-6851 | D14: R1-450 | E14: Depok | F14: 219 | G14: Lunas
A15: TRX0014 | B15: 46256 | C15: PLN-1916 | D15: B1-900 | E15: Jakarta | F15: 41 | G15: Lunas
A16: TRX0015 | B16: 46256 | C16: PLN-3184 | D16: R1-1300 | E16: Tangerang | F16: 61 | G16: Lunas
A17: TRX0016 | B17: 46248 | C17: PLN-1011 | D17: R1-1300 | E17: Jakarta | F17: 155 | G17: Tunggakan
A18: TRX0017 | B18: 46334 | C18: PLN-5473 | D18: B1-1300 | E18: Jakarta | F18: 118 | G18: Lunas
A19: TRX0018 | B19: 46251 | C19: PLN-7941 | D19: B1-450 | E19: Depok | F19: 225 | G19: Lunas
A20: TRX0019 | B20: 46259 | C20: PLN-9733 | D20: R1-900 | E20: Jakarta | F20: 127 | G20: Lunas
A21: TRX0020 | B21: 46030 | C21: PLN-4266 | D21: R1-900 | E21: Depok | F21: 62 | G21: Lunas
A22: TRX0021 | B22: 46264 | C22: PLN-2965 | D22: R1-450 | E22: Tangerang | F22: 317 | G22: Lunas
... A25: TRX0024 | B25: 46248 | C25: PLN-3918 | D25: B1-1300 | E25: Tangerang | F25: 132 | G25: Tunggakan
A26: TRX0025 | B26: 46257 | C26: PLN-6481 | D26: R1-1300 | F26: 156 | G26: Lunas
A27: TRX0026 | B27: 46334 | C27: PLN-4683 | D27: B1-1300 | E27: Jakarta | F27: 208 | G27: Lunas
A28: TRX0027 | B28: 46242 | C28: PLN-1659 | D28: B1-1300 | E28: Bogor | F28: 107 | G28: Lunas
A29: TRX0028 | B29: 46263 | C29: PLN-3304 | D29: R1-900 | E29: Depok | F29: 230 | G29: Lunas
A30: TRX0029 | B30: 46254 | C30: PLN-1785 | D30: R1-450 | E30: Jakarta | F30: 151 | G30: Lunas
A31: TRX0030 | B31: 46262 | C31: PLN-8800 | D31: B1-1300 | E31: Depok | F31: 176 | G31: Tunggakan
A32: TRX0031 | B32: 46257 | C32: PLN-3183 | D32: B1-450 | E32: Bogor | F32: 151 | G32: Lunas
A33: TRX0032 | B33: 46257 | C33: PLN-3323 | D33: B1-900 | E33: Tngrang | F33: 348 | G33: Lunas
A34: TRX0033 | B34: 46260 | C34: PLN-1903 | D34: B1-450 | E34: Depok | F34: 198 | G34: Lunas
A35: TRX0034 | B35: 46252 | C35: PLN-1934 | D35: B1-900 | E35: Bekasi | F35: 115 | G35: Tunggakan
A36: TRX0035 | B36: 46030 | C36: PLN-7690 | D36: R1-900 | E36: Jakarta | F36: 265 | G36: Tunggakan
A37: TRX0036 | B37: 46254 | C37: PLN-9491 | D37: R1-1300 | E37: Bekasi | F37: 102 | G37: Lunas
A38: TRX0037 | B38: 46263 | C38: PLN-1411 | D38: R1-1300 | E38: Bekasi | F38: 216 | G38: Lunas
... A43: TRX0042 | B43: 46256 | C43: PLN-4264 | D43: R1-450 | E43: Tangerang | F43: 213 | G43: Lunas
A44: TRX0043 | B44: 46248 | D44: R1-900 | E44: Bekasi | F44: 190 | G44: Lunas
A45: TRX0044 | B45: 46256 | C45: PLN-2287 | D45: B1-450 | E45: Depok | F45: 175 | G45: Lunas
A46: TRX0045 | B46: 46263 | C46: PLN-4905 | D46: R1-1300 | E46: Bogor | F46: 163 | G46: Lunas
...

Sheet 2. Data Validation
A1: ID_Transaksi | B1: Tanggal | C1: ID_Pelanggan | D1: ID_Layanan | E1: Area | F1: KWh_Terpakai | G1: Status_Bayar
A2: TRX0087 | B2: 46089 | C2: PLN-9029 | D2: R1-900 | E2: Bogor | F2: 5000 | G2: Lunas | I2: Average | J2: =AVERAGE(F2:F126) -> 248.52
A3: TRX0095 | B3: 46061 | C3: PLN-1498 | D3: B1-900 | E3: Jakarta | F3: 385 | G3: Lunas | I3: Min | J3: =MIN(F2:F126) -> -50
A4: TRX0038 | B4: 46253 | C4: PLN-7965 | D4: R1-900 | E4: Bogor | F4: 356 | G4: Lunas | I4: Max | J4: =MAX(F2:F126) -> 5000
A5: TRX0066 | B5: 46262 | C5: PLN-3127 | D5: B1-450 | E5: Tngrang | F5: 355 | G5: Lunas | I5: Sel Kosong | J5: =COUNTBLANK(A2:G126) -> 13
A6: TRX0085 | B6: 46261 | C6: PLN-3522 | D6: R1-450 | E6: Bogor | F6: 352 | G6: Lunas | J6: Duplicate Data
A7: TRX0032 | B7: 46257 | C7: PLN-3323 | D7: B1-900 | E7: Tngrang | F7: 348 | G7: Lunas | J7: Inkonsistensi Format
A8: TRX0090 | B8: 46248 | C8: PLN-6330 | D8: B1-900 | E8: jkt | F8: 345 | G8: Lunas
A9: TRX0007 | B9: 46242 | C9: PLN-7572 | D9: B1-450 | E9: Jakarta | F9: 326 | G9: Lunas
A10: TRX0073 | B10: 46254 | C10: PLN-2693 | D10: B1-450 | E10: Bekasi | F10: 326 | G10: Tunggakan
A11: TRX0107 | B11: 46265 | C11: PLN-4266 | D11: B1-450 | E11: Bekasi | F11: 325 | G11: Tunggakan
A12: TRX0089 | B12: 46273 | C12: PLN-9572 | D12: R1-1300 | E12: Jakarta | F12: 323 | G12: Tunggakan
A13: TRX0084 | B13: 46303 | C13: PLN-4447 | D13: R1-450 | E13: Tangerang | F13: 322 | G13: Lunas
A14: TRX0004 | B14: 46258 | C14: PLN-4752 | D14: R1-450 | E14: jkt | F14: 321 | G14: Lunas
A15: TRX0021 | B15: 46264 | C15: PLN-2965 | D15: R1-450 | E15: Tangerang | F15: 317 | G15: Lunas
A16: TRX0117 | B16: 46265 | C16: PLN-2965 | D16: B1-1300 | E16: Jakarta | F16: 313 | G16: Lunas
A17: TRX0048 | B17: 46030 | C17: PLN-1335 | D17: B1-1300 | E17: Bogor | F17: 284 | G17: Lunas
A18: TRX0108 | B18: 46364 | C18: PLN-8452 | D18: B1-900 | E18: Depok | F18: 282 | G18: Lunas
A19: TRX0060 | B19: 46211 | C19: PLN-4573 | D19: R1-900 | E19: Depok | F19: 278 | G19: Tunggakan
A20: TRX0067 | B20: 46250 | C20: PLN-8072 | D20: B1-450 | E20: Jakarta | F20: 276 | G20: Lunas
A21: TRX0061 | B21: 46120 | C21: PLN-8745 | D21: B1-450 | F21: 272 | G21: Lunas
A22: TRX0088 | B22: 46264 | C22: PLN-1718 | D22: R1-900 | E22: Tangerang | F22: 270 | G22: Tunggakan
A23: TRX0118 | B23: 46259 | C23: PLN-6338 | D23: R1-900 | E23: Tangerang | F23: 270 | G23: Lunas
A24: TRX0120 | B24: 46263 | C24: PLN-9028 | D24: B1-900 | E24: BOGOR | F24: 270 | G24: Tunggakan
A25: TRX0118 | B25: 46259 | C25: PLN-6338 | D25: R1-900 | E25: Tangerang | F25: 270 | G25: Lunas
A26: TRX0057 | B26: 46255 | C26: PLN-7577 | D26: R1-450 | E26: Tangerang | F26: 267 | G26: Tunggakan
A27: TRX0035 | B27: 46030 | C27: PLN-7690 | D27: R1-900 | E27: Jakarta | F27: 265 | G27: Tunggakan
A28: TRX0008 | B28: 46150 | C28: PLN-5386 | D28: R1-1300 | E28: Bekasi | F28: 261 | G28: Lunas
A29: TRX0097 | B29: 46364 | C29: PLN-1886 | D29: R1-900 | F29: 261 | G29: Lunas
A30: TRX0114 | B30: 46265 | C30: PLN-6944 | D30: B1-1300 | E30: Bogor | F30: 259 | G30: Lunas
A31: TRX0041 | B31: 46254 | C31: PLN-2325 | D31: B1-1300 | E31: Tangerang | F31: 258 | G31: Lunas
A32: TRX0003 | B32: 46030 | C32: PLN-1916 | D32: R1-900 | E32: Tangerang | F32: 251 | G32: Lunas
A33: TRX0111 | B33: 46303 | C33: PLN-3158 | D33: B1-1300 | E33: Jakarta | F33: 251 | G33: Tunggakan
A34: TRX0074 | B34: 46364 | C34: PLN-5735 | D34: R1-1300 | E34: Tangerang | F34: 246 | G34: Lunas
A35: TRX0116 | B35: 46242 | C35: PLN-2117 | D35: B1-1300 | F35: 245 | G35: Tunggakan
A36: TRX0010 | B36: 46257 | C36: PLN-9494 | D36: R1-1300 | E36: Tangerang | F36: 243 | G36: Tunggakan
A37: TRX0010 | B37: 46257 | C37: PLN-9494 | D37: R1-1300 | E37: Tangerang | F37: 243 | G37: Tunggakan
A38: TRX0109 | B38: 46258 | C38: PLN-7679 | D38: R1-450 | E38: Bogor | F38: 240 | G38: Lunas
A39: TRX0001 | B39: 46255 | C39: PLN-4598 | D39: B1-450 | F39: 239 | G39: Lunas
A40: TRX0110 | B40: 46258 | C40: PLN-1405 | D40: B1-900 | E40: Jakarta | F40: 238 | G40: Lunas
...

Sheet 3. Data Cleaning
A1: ID_Transaksi | B1: Tanggal | C1: ID_Pelanggan | D1: ID_Layanan | E1: Area | F1: KWh_Terpakai | G1: Status_Bayar
A2: TRX0053 | B2: 46120 | C2: PLN-8438 | D2: R1-1300 | E2: Bekasi | F2: 218 | G2: Lunas | I2: Average | J2: =AVERAGE(F2:F126) -> 213.66667
A3: TRX0014 | B3: 46256 | C3: PLN-1916 | D3: B1-900 | E3: Jakarta | F3: 41 | G3: Lunas | I3: Min | J3: =MIN(F2:F126) -> 41
A4: TRX0015 | B4: 46256 | C4: PLN-3184 | D4: R1-1300 | E4: Tangerang | F4: 61 | G4: Lunas | I4: Max | J4: =MAX(F2:F126) -> 385
A5: TRX0020 | B5: 46030 | C5: PLN-4266 | D5: R1-900 | E5: Depok | F5: 62 | G5: Lunas | I5: Sel Kosong | J5: =COUNTBLANK(E2:E121) -> 0
A6: TRX0096 | B6: 46030 | C6: PLN-5900 | D6: R1-1300 | E6: Depok | F6: 82 | G6: Lunas | I6: MEDIAN | J6: =MEDIAN(F2:F126) -> 218.5
A7: TRX0039 | B7: 46030 | C7: PLN-3736 | D7: B1-450 | E7: Depok | F7: 93 | G7: Lunas
A8: TRX0036 | B8: 46254 | C8: PLN-9491 | D8: R1-1300 | E8: Bekasi | F8: 102 | G8: Lunas
A9: TRX0077 | B9: 46263 | C9: PLN-4428 | D9: B1-900 | E9: Jakarta | F9: 105 | G9: Tunggakan
A10: TRX0027 | B10: 46242 | C10: PLN-1659 | D10: B1-1300 | E10: Bogor | F10: 107 | G10: Lunas
A11: TRX0034 | B11: 46252 | C11: PLN-1934 | D11: B1-900 | E11: Bekasi | F11: 115 | G11: Tunggakan
A12: TRX0017 | B12: 46334 | C12: PLN-5473 | D12: B1-1300 | E12: Jakarta | F12: 118 | G12: Lunas
A13: TRX0119 | B13: 46250 | C13: PLN-8114 | D13: B1-900 | E13: Depok | F13: 119 | G13: Lunas
A14: TRX0070 | B14: 46181 | C14: PLN-8276 | D14: B1-1300 | E14: Bogor | F14: 120 | G14: Tunggakan
A15: TRX0071 | B15: 46181 | C15: PLN-5497 | D15: R1-900 | E15: Tangerang | F15: 126 | G15: Lunas
A16: TRX0019 | B16: 46259 | C16: PLN-9733 | D16: R1-900 | E16: Jakarta | F16: 127 | G16: Lunas
A17: TRX0069 | B17: 46120 | C17: PLN-6582 | D17: R1-1300 | E17: Depok | F17: 127 | G17: Lunas
A18: TRX0024 | B18: 46248 | C18: PLN-3918 | D18: B1-1300 | E18: Tangerang | F18: 132 | G18: Tunggakan
... A121: TRX0095 | B121: 46061 | C121: PLN-1498 | D121: B1-900 | E121: Jakarta | F121: 385 | G121: Lunas

Sheet 4. Data Integgration
A1: ID_Transaksi | B1: Tanggal | C1: ID_Pelanggan | D1: Nama_Pelanggan | E1: Segmen_Pelanggan | F1: ID_Layanan | G1: Nama_Layanan | H1: Tarif_per_KWH | I1: Area | J1: KWh_Terpakai | K1: Status_Bayar
A2: TRX0053 | B2: 46120 | C2: PLN-8438 | D2: {=_xlfn.XLOOKUP(C2,Master_Pelanggan!A:A,Master_Pelanggan!B:B)} -> Nur Siregar | E2: {=_xlfn.XLOOKUP(C2,Master_Pelanggan!A:A,Master_Pelanggan!D:D)} -> Reguler | F2: R1-1300 | G2: {=IF(F2:F1000="", "", VLOOKUP(F2:F1000, 'Master Layanan PLN'!$A$2:$C$7, 2, FALSE))} -> Rumah Tangga 1300 VA | H2: {=IF(G2:G1000="", "", VLOOKUP(F2:F1000, 'Master Layanan PLN'!$A$2:$C$7, 3, FALSE))} -> 1444 | I2: Bekasi | J2: 218 | K2: Lunas
A3: TRX0014 | B3: 46256 | C3: PLN-1916 | D3: {=_xlfn.XLOOKUP(C3,Master_Pelanggan!A:A,Master_Pelanggan!B:B)} -> Siti Saputra | E3: {=_xlfn.XLOOKUP(C3,Master_Pelanggan!A:A,Master_Pelanggan!D:D)} -> Reguler | F3: B1-900 | G3: Bisnis 900 VA | H3: 633 | I3: Jakarta | J3: 41 | K3: Lunas
A4: TRX0015 | B4: 46256 | C4: PLN-3184 | D4: {=_xlfn.XLOOKUP(C4,Master_Pelanggan!A:A,Master_Pelanggan!B:B)} -> Rina Hidayat | E4: {=_xlfn.XLOOKUP(C4,Master_Pelanggan!A:A,Master_Pelanggan!D:D)} -> Reguler | F4: R1-1300 | G4: Rumah Tangga 1300 VA | H4: 1444 | I4: Tangerang | J4: 61 | K4: Lunas
A5: TRX0020 | B5: 46030 | C5: PLN-4266 | D5: {=_xlfn.XLOOKUP(C5,Master_Pelanggan!A:A,Master_Pelanggan!B:B)} -> Nina Syahputra | E5: {=_xlfn.XLOOKUP(C5,Master_Pelanggan!A:A,Master_Pelanggan!D:D)} -> Reguler | F5: R1-900 | G5: Rumah Tangga 900 VA | H5: 1352 | I5: Depok | J5: 62 | K5: Lunas
A6: TRX0096 | B6: 46030 | C6: PLN-5900 | D6: {=_xlfn.XLOOKUP(C6,Master_Pelanggan!A:A,Master_Pelanggan!B:B)} -> Ari Rahayu | E6: {=_xlfn.XLOOKUP(C6,Master_Pelanggan!A:A,Master_Pelanggan!D:D)} -> Reguler | F6: R1-1300 | G6: Rumah Tangga 1300 VA | H6: 1444 | I6: Depok | J6: 82 | K6: Lunas
A7: TRX0039 | B7: 46030 | C7: PLN-3736 | D7: {=_xlfn.XLOOKUP(C7,Master_Pelanggan!A:A,Master_Pelanggan!B:B)} -> Lia Wahyuni | E7: {=_xlfn.XLOOKUP(C7,Master_Pelanggan!A:A,Master_Pelanggan!D:D)} -> Reguler | F7: B1-450 | G7: Bisnis 450 VA | H7: 535 | I7: Depok | J7: 93 | K7: Lunas
A8: TRX0036 | B8: 46254 | C8: PLN-9491 | D8: {=_xlfn.XLOOKUP(C8,Master_Pelanggan!A:A,Master_Pelanggan!B:B)} -> Dwi Hidayat | E8: {=_xlfn.XLOOKUP(C8,Master_Pelanggan!A:A,Master_Pelanggan!D:D)} -> Prioritas | F8: R1-1300 | G8: Rumah Tangga 1300 VA | H8: 1444 | I8: Bekasi | J8: 102 | K8: Lunas
A9: TRX0077 | B9: 46263 | C9: PLN-4428 | D9: {=_xlfn.XLOOKUP(C9,Master_Pelanggan!A:A,Master_Pelanggan!B:B)} -> Rina Wijaya | E9: {=_xlfn.XLOOKUP(C9,Master_Pelanggan!A:A,Master_Pelanggan!D:D)} -> Reguler | F9: B1-900 | G9: Bisnis 900 VA | H9: 633 | I9: Jakarta | J9: 105 | K9: Tunggakan
A10: TRX0027 | B10: 46242 | C10: PLN-1659 | D10: {=_xlfn.XLOOKUP(C10,Master_Pelanggan!A:A,Master_Pelanggan!B:B)} -> Dwi Santoso | E10: {=_xlfn.XLOOKUP(C10,Master_Pelanggan!A:A,Master_Pelanggan!D:D)} -> Prioritas | F10: B1-1300 | G10: Bisnis 1300 VA | H10: 966 | I10: Bogor | J10: 107 | K10: Lunas
A11: TRX0034 | B11: 46252 | C11: PLN-1934 | D11: {=_xlfn.XLOOKUP(C11,Master_Pelanggan!A:A,Master_Pelanggan!B:B)} -> Dwi Wibowo | E11: {=_xlfn.XLOOKUP(C11,Master_Pelanggan!A:A,Master_Pelanggan!D:D)} -> Prioritas | F11: B1-900 | G11: Bisnis 900 VA | H11: 633 | I11: Bekasi | J11: 115 | K11: Tunggakan
A12: TRX0017 | B12: 46334 | C12: PLN-5473 | D12: {=_xlfn.XLOOKUP(C12,Master_Pelanggan!A:A,Master_Pelanggan!B:B)} -> Eko Nugroho | E12: {=_xlfn.XLOOKUP(C12,Master_Pelanggan!A:A,Master_Pelanggan!D:D)} -> Reguler | F12: B1-1300 | G12: Bisnis 1300 VA | H12: 966 | I12: Jakarta | J12: 118 | K12: Lunas
A13: TRX0119 | B13: 46250 | C13: PLN-8114 | D13: {=_xlfn.XLOOKUP(C13,Master_Pelanggan!A:A,Master_Pelanggan!B:B)} -> Rudi Nugroho | E13: {=_xlfn.XLOOKUP(C13,Master_Pelanggan!A:A,Master_Pelanggan!D:D)} -> Subsidi | F13: B1-900 | G13: Bisnis 900 VA | H13: 633 | I13: Depok | J13: 119 | K13: Lunas
A14: TRX0070 | B14: 46181 | C14: PLN-8276 | D14: {=_xlfn.XLOOKUP(C14,Master_Pelanggan!A:A,Master_Pelanggan!B:B)} -> Ahmad Nugroho | E14: {=_xlfn.XLOOKUP(C14,Master_Pelanggan!A:A,Master_Pelanggan!D:D)} -> Reguler | F14: B1-1300 | G14: Bisnis 1300 VA | H14: 966 | I14: Bogor | J14: 120 | K14: Tunggakan
... A121: TRX0095 | B121: 46061 | C121: PLN-1498 | D121: {=_xlfn.XLOOKUP(C121,Master_Pelanggan!A:A,Master_Pelanggan!B:B)} -> Indah Santoso | E121: {=_xlfn.XLOOKUP(C121,Master_Pelanggan!A:A,Master_Pelanggan!D:D)} -> Reguler | F121: B1-900 | G121: Bisnis 900 VA | H121: 633 | I121: Jakarta | J121: 385 | K121: Lunas

Sheet 5. Feature Engineering
A1: ID_Transaksi | B1: Tanggal | C1: ID_Pelanggan | D1: Nama_Pelanggan | E1: Segmen_Pelanggan | F1: ID_Layanan | G1: Nama_Layanan | H1: Tarif_per_KWH | I1: Area | J1: KWh_Terpakai | K1: Status_Bayar | L1: Total_Tagihan
A2: TRX0053 | B2: 46120 | C2: PLN-8438 | D2: {=_xlfn.XLOOKUP(C2,Master_Pelanggan!A:A,Master_Pelanggan!B:B)} -> Nur Siregar | E2: {=_xlfn.XLOOKUP(C2,Master_Pelanggan!A:A,Master_Pelanggan!D:D)} -> Reguler | F2: R1-1300 | G2: {=IF(F2:F1000="", "", VLOOKUP(F2:F1000, 'Master Layanan PLN'!$A$2:$C$7, 2, FALSE))} -> Rumah Tangga 1300 VA | H2: {=IF(G2:G1000="", "", VLOOKUP(F2:F1000, 'Master Layanan PLN'!$A$2:$C$7, 3, FALSE))} -> 1444 | I2: Bekasi | J2: 218 | K2: Lunas | L2: =H2*J2 -> 314792
A3: TRX0014 | B3: 46256 | C3: PLN-1916 | D3: {=_xlfn.XLOOKUP(C3,Master_Pelanggan!A:A,Master_Pelanggan!B:B)} -> Siti Saputra | E3: {=_xlfn.XLOOKUP(C3,Master_Pelanggan!A:A,Master_Pelanggan!D:D)} -> Reguler | F3: B1-900 | G3: Bisnis 900 VA | H3: 633 | I3: Jakarta | J3: 41 | K3: Lunas | L3: =H3*J3 -> 25953
A4: TRX0015 | B4: 46256 | C4: PLN-3184 | D4: {=_xlfn.XLOOKUP(C4,Master_Pelanggan!A:A,Master_Pelanggan!B:B)} -> Rina Hidayat | E4: {=_xlfn.XLOOKUP(C4,Master_Pelanggan!A:A,Master_Pelanggan!D:D)} -> Reguler | F4: R1-1300 | G4: Rumah Tangga 1300 VA | H4: 1444 | I4: Tangerang | J4: 61 | K4: Lunas | L4: =H4*J4 -> 88084
A5: TRX0020 | B5: 46030 | C5: PLN-4266 | D5: {=_xlfn.XLOOKUP(C5,Master_Pelanggan!A:A,Master_Pelanggan!B:B)} -> Nina Syahputra | E5: {=_xlfn.XLOOKUP(C5,Master_Pelanggan!A:A,Master_Pelanggan!D:D)} -> Reguler | F5: R1-900 | G5: Rumah Tangga 900 VA | H5: 1352 | I5: Depok | J5: 62 | K5: Lunas | L5: =H5*J5 -> 83824
A6: TRX0096 | B6: 46030 | C6: PLN-5900 | D6: {=_xlfn.XLOOKUP(C6,Master_Pelanggan!A:A,Master_Pelanggan!B:B)} -> Ari Rahayu | E6: {=_xlfn.XLOOKUP(C6,Master_Pelanggan!A:A,Master_Pelanggan!D:D)} -> Reguler | F6: R1-1300 | G6: Rumah Tangga 1300 VA | H6: 1444 | I6: Depok | J6: 82 | K6: Lunas | L6: =H6*J6 -> 118408
A7: TRX0039 | B7: 46030 | C7: PLN-3736 | D7: {=_xlfn.XLOOKUP(C7,Master_Pelanggan!A:A,Master_Pelanggan!B:B)} -> Lia Wahyuni | E7: {=_xlfn.XLOOKUP(C7,Master_Pelanggan!A:A,Master_Pelanggan!D:D)} -> Reguler | F7: B1-450 | G7: Bisnis 450 VA | H7: 535 | I7: Depok | J7: 93 | K7: Lunas | L7: =H7*J7 -> 49755
A8: TRX0036 | B8: 46254 | C8: PLN-9491 | D8: {=_xlfn.XLOOKUP(C8,Master_Pelanggan!A:A,Master_Pelanggan!B:B)} -> Dwi Hidayat | E8: {=_xlfn.XLOOKUP(C8,Master_Pelanggan!A:A,Master_Pelanggan!D:D)} -> Prioritas | F8: R1-1300 | G8: Rumah Tangga 1300 VA | H8: 1444 | I8: Bekasi | J8: 102 | K8: Lunas | L8: =H8*J8 -> 147288
A9: TRX0077 | B9: 46263 | C9: PLN-4428 | D9: {=_xlfn.XLOOKUP(C9,Master_Pelanggan!A:A,Master_Pelanggan!B:B)} -> Rina Wijaya | E9: {=_xlfn.XLOOKUP(C9,Master_Pelanggan!A:A,Master_Pelanggan!D:D)} -> Reguler | F9: B1-900 | G9: Bisnis 900 VA | H9: 633 | I9: Jakarta | J9: 105 | K9: Tunggakan | L9: =H9*J9 -> 66465
A10: TRX0027 | B10: 46242 | C10: PLN-1659 | D10: {=_xlfn.XLOOKUP(C10,Master_Pelanggan!A:A,Master_Pelanggan!B:B)} -> Dwi Santoso | E10: {=_xlfn.XLOOKUP(C10,Master_Pelanggan!A:A,Master_Pelanggan!D:D)} -> Prioritas | F10: B1-1300 | G10: Bisnis 1300 VA | H10: 966 | I10: Bogor | J10: 107 | K10: Lunas | L10: =H10*J10 -> 103362
A11: TRX0034 | B11: 46252 | C11: PLN-1934 | D11: {=_xlfn.XLOOKUP(C11,Master_Pelanggan!A:A,Master_Pelanggan!B:B)} -> Dwi Wibowo | E11: {=_xlfn.XLOOKUP(C11,Master_Pelanggan!A:A,Master_Pelanggan!D:D)} -> Prioritas | F11: B1-900 | G11: Bisnis 900 VA | H11: 633 | I11: Bekasi | J11: 115 | K11: Tunggakan | L11: =H11*J11 -> 72795
A12: TRX0017 | B12: 46334 | C12: PLN-5473 | D12: {=_xlfn.XLOOKUP(C12,Master_Pelanggan!A:A,Master_Pelanggan!B:B)} -> Eko Nugroho | E12: {=_xlfn.XLOOKUP(C12,Master_Pelanggan!A:A,Master_Pelanggan!D:D)} -> Reguler | F12: B1-1300 | G12: Bisnis 1300 VA | H12: 966 | I12: Jakarta | J12: 118 | K12: Lunas | L12: =H12*J12 -> 113988
A13: TRX0119 | B13: 46250 | C13: PLN-8114 | D13: {=_xlfn.XLOOKUP(C13,Master_Pelanggan!A:A,Master_Pelanggan!B:B)} -> Rudi Nugroho | E13: {=_xlfn.XLOOKUP(C13,Master_Pelanggan!A:A,Master_Pelanggan!D:D)} -> Subsidi | F13: B1-900 | G13: Bisnis 900 VA | H13: 633 | I13: Depok | J13: 119 | K13: Lunas | L13: =H13*J13 -> 75327
A14: TRX0070 | B14: 46181 | C14: PLN-8276 | D14: {=_xlfn.XLOOKUP(C14,Master_Pelanggan!A:A,Master_Pelanggan!B:B)} -> Ahmad Nugroho | E14: {=_xlfn.XLOOKUP(C14,Master_Pelanggan!A:A,Master_Pelanggan!D:D)} -> Reguler | F14: B1-1300 | G14: Bisnis 1300 VA | H14: 966 | I14: Bogor | J14: 120 | K14: Tunggakan | L14: =H14*J14 -> 115920
... A121: TRX0095 | B121: 46061 | C121: PLN-1498 | D121: {=_xlfn.XLOOKUP(C121,Master_Pelanggan!A:A,Master_Pelanggan!B:B)} -> Indah Santoso | E121: {=_xlfn.XLOOKUP(C121,Master_Pelanggan!A:A,Master_Pelanggan!D:D)} -> Reguler | F121: B1-900 | G121: Bisnis 900 VA | H121: 633 | I121: Jakarta | J121: 385 | K121: Lunas | L121: =H121*J121 -> 243705

Sheet Pivot Table 1

Sheet Master Layanan PLN
A1: ID_Layanan | B1: Nama_Layanan | C1: Tarif_per_kWh
A2: R1-450 | B2: Rumah Tangga 450 VA | C2: 415
A3: R1-900 | B3: Rumah Tangga 900 VA | C3: 1352
A4: R1-1300 | B4: Rumah Tangga 1300 VA | C4: 1444
A5: B1-450 | B5: Bisnis 450 VA | C5: 535
A6: B1-900 | B6: Bisnis 900 VA | C6: 633
A7: B1-1300 | B7: Bisnis 1300 VA | C7: 966

Sheet Master_Pelanggan
A1: ID_Pelanggan | B1: Nama_Pelanggan | C1: No_HP | D1: Segmen_Pelanggan | E1: Tahun_Pasang
A2: PLN-4598 | B2: Ahmad Setiawan | C2: 8125614226 | D2: Reguler | E2: 2018
A3: PLN-6313 | B3: Agus Setiawan | C3: 8962458591 | D3: Subsidi | E3: 2021
A4: PLN-1916 | B4: Siti Saputra | C4: 8124668136 | D4: Reguler | E4: 2023
A5: PLN-4752 | B5: Maya Saputra | C5: 8574335942 | D5: Subsidi | E5: 2021
A6: PLN-1525 | B6: Ayu Astuti | C6: 8575667265 | D6: Reguler | E6: 2017
A7: PLN-6168 | B7: Muhammad Kurniawan | C7: 8525661907 | D7: Reguler | E7: 2018
A8: PLN-7572 | B8: Dwi Santoso | C8: 8122556017 | D8: Prioritas | E8: 2016
A9: PLN-5386 | B9: Rina Sari | C9: 8575437923 | D9: Reguler | E9: 2022
A10: PLN-9494 | B10: Lia Setiawan | C10: 8532322047 | D10: Subsidi | E10: 2019
A11: PLN-1132 | B11: Tri Suharto | C11: 8524226067 | D11: Reguler | E11: 2015
A12: PLN-2321 | B12: Nur Wahyuni | C12: 8522338687 | D12: Reguler | E12: 2016
A13: PLN-6851 | B13: Eko Nugroho | C13: 8537120868 | D13: Reguler | E13: 2020
... A104: PLN-9028 | B104: Ahmad Wahyuni | C104: 8528379837 | D104: Reguler | E104: 2019
